Workbook

Sheet DATOS AGENTE
D4: 328 | J4: ID EMPL | L4: =VLOOKUP(D4,BBDD!A2:BR570,2,FALSE) -> 41U639 | O4: SEGMENTO | R4: =VLOOKUP(D4,BBDD!A2:BR570,10,FALSE) -> ESTÁNDAR | W4: FORMACIÓN ESTANDAR | AC4: FORMACIÓN JURIDICO
J5: ID BOOST | L5: =VLOOKUP(D4,BBDD!A2:BR570,3,FALSE) -> 9007730 | O5: IDIOMA | R5: =VLOOKUP(D4,BBDD!A2:BR570,11,FALSE) -> FRANCES
J6: DNI | L6: =VLOOKUP(D4,BBDD!A2:BR570,4,FALSE) -> 29506767K | O6: COORDINADOR | R6: =VLOOKUP(D4,BBDD!A2:BR570,13,FALSE) -> TANYA JASMINA ASSIMI CRUZ | W6: =BBDD!AG1 -> USER SYR | Y6: =VLOOKUP(D$4,BBDD!A$2:BR$570,33,FALSE) -> 0 | AC6: =BBDD!BH1 -> LIVECHAT | AE6: =VLOOKUP(D$4,BBDD!A$2:BR$570,60,FALSE) -> #N/A
W8: =BBDD!AH1 -> LLAMADAS | Y8: =VLOOKUP(D$4,BBDD!A$2:BR$570,34,FALSE) -> 45810 | AC8: =BBDD!BI1 -> INCIVIA | AE8: =VLOOKUP(D$4,BBDD!A$2:BR$570,61,FALSE) -> #N/A
C10: DATOS DE LOGIN Y HERRAMIENTAS | J10: HORARIO 14-09 al 20-10 | W10: =BBDD!AI1 -> ASIGNACION | Y10: =VLOOKUP(D$4,BBDD!A$2:BR$570,35,FALSE) -> 45810 | AC10: =BBDD!BJ1 -> INSTRUCCIONES | AE10: =VLOOKUP(D$4,BBDD!A$2:BR$570,62,FALSE) -> #N/A
D12: TELÉFONO | F12: =VLOOKUP(D4,BBDD!A2:BR570,6,FALSE) -> 640267366 | J12: LUNES | L12: =VLOOKUP(D4,BBDD!A2:BR570,15,FALSE) -> 13_20 | W12: =BBDD!AJ1 -> BO EQUIPAJE | Y12: =VLOOKUP(D$4,BBDD!A$2:BR$570,36,FALSE) -> 45810 | AC12: =BBDD!BK1 -> DESKTOP | AE12: =VLOOKUP(D$4,BBDD!A$2:BR$570,63,FALSE) -> #N/A
D14: EMEA | F14: =VLOOKUP(D4,BBDD!A2:BR570,23,FALSE) -> ccort109 | J14: MARTES | L14: =VLOOKUP(D4,BBDD!A2:BR570,16,FALSE) -> LIBRA | W14: =BBDD!AK1 -> BO PASAJE | Y14: =VLOOKUP(D$4,BBDD!A$2:BR$570,37,FALSE) -> 45810 | AC14: =BBDD!BL1 -> TRAIN ESTANDAR | AE14: =VLOOKUP(D$4,BBDD!A$2:BR$570,64,FALSE) -> 0
D16: CORREO | F16: =VLOOKUP(D4,BBDD!A2:BR570,24,FALSE) -> ccort109@ec.foundever.com | J16: MIÉRCOLES | L16: =VLOOKUP(D4,BBDD!A2:BR570,17,FALSE) -> 12_20 | W16: =BBDD!AL1 -> VIP | Y16: =VLOOKUP(D$4,BBDD!A$2:BR$570,38,FALSE) -> #N/A | AC16: =BBDD!BM1 -> ASIGNACION | AE16: =VLOOKUP(D$4,BBDD!A$2:BR$570,65,FALSE) -> #N/A
D18: LOGIN | F18: =VLOOKUP(D4,BBDD!A2:BR570,25,FALSE) -> 3485993 | J18: JUEVES | L18: =VLOOKUP(D4,BBDD!A2:BR570,18,FALSE) -> LFS_12_20 | W18: =BBDD!AM1 -> REDES/PRENSA | Y18: =VLOOKUP(D$4,BBDD!A$2:BR$570,39,FALSE) -> #N/A | AC18: =BBDD!BN1 -> ABOGADOS_EERR | AE18: =VLOOKUP(D$4,BBDD!A$2:BR$570,66,FALSE) -> #N/A
D20: EXTENSIÓN | F20: =VLOOKUP(D4,BBDD!A2:BR570,26,FALSE) -> 3486499 | J20: VIERNES | L20: =VLOOKUP(D4,BBDD!A2:BR570,19,FALSE) -> LIBRA | W20: =BBDD!AN1 -> RPM | Y20: =VLOOKUP(D$4,BBDD!A$2:BR$570,40,FALSE) -> #N/A | AC20: =BBDD!BO1 -> DEMANDAS ESP | AE20: =VLOOKUP(D$4,BBDD!A$2:BR$570,67,FALSE) -> #N/A
D22: DOMINIO | F22: =VLOOKUP(D4,BBDD!A2:BR570,28,FALSE) -> FOUND.CCORTON | J22: SÁBADO | L22: =VLOOKUP(D4,BBDD!A2:BR570,20,FALSE) -> 13_20 | W22: =BBDD!AO1 -> INFINITA | Y22: =VLOOKUP(D$4,BBDD!A$2:BR$570,41,FALSE) -> #N/A | AC22: =BBDD!BP1 -> AESA | AE22: =VLOOKUP(D$4,BBDD!A$2:BR$570,68,FALSE) -> #N/A
D24: CALLCENTER | F24: =VLOOKUP(D4,BBDD!A2:BR570,29,FALSE) -> CCORTONJ | J24: DOMINGO | L24: =VLOOKUP(D4,BBDD!A2:BR570,21,FALSE) -> 12_20 | W24: =BBDD!AP1 -> OW/AJB | Y24: =VLOOKUP(D$4,BBDD!A$2:BR$570,42,FALSE) -> #N/A | AC24: =BBDD!BQ1 -> OMICs | AE24: =VLOOKUP(D$4,BBDD!A$2:BR$570,69,FALSE) -> #N/A
D26: RESIBER | F26: =VLOOKUP(D4,BBDD!A2:BR570,30,FALSE) -> 5778 | W26: =BBDD!AQ1 -> ATENCION PERSONAL/FELICITACIONES/SUGERENCIA/AGRADECIMIENTO | Y26: =VLOOKUP(D$4,BBDD!A$2:BR$570,43,FALSE) -> #N/A | AC26: =BBDD!BR1 -> PAGOS ESPAÑA | AE26: =VLOOKUP(D$4,BBDD!A$2:BR$570,70,FALSE) -> #N/A
D28: AMADEUS | F28: =VLOOKUP(D4,BBDD!A2:BR570,31,FALSE) -> 5778CC | W28: =BBDD!AR1 -> PMR/LESIONADOS/INTOX | Y28: =VLOOKUP(D$4,BBDD!A$2:BR$570,44,FALSE) -> #N/A
W30: =BBDD!AS1 -> TASAS CHILE | Y30: =VLOOKUP(D$4,BBDD!A$2:BR$570,45,FALSE) -> #N/A
W32: =BBDD!AT1 -> FUTUROS VUELOS | Y32: =VLOOKUP(D$4,BBDD!A$2:BR$570,46,FALSE) -> #N/A
W34: =BBDD!AU1 -> YQ | Y34: =VLOOKUP(D$4,BBDD!A$2:BR$570,47,FALSE) -> #N/A
W36: =BBDD!AV1 -> REEMBOLSOS PARCIAL Y TARIFA | Y36: =VLOOKUP(D$4,BBDD!A$2:BR$570,48,FALSE) -> #N/A
W38: =BBDD!AW1 -> REEMBOLSO TOTAL | Y38: =VLOOKUP(D$4,BBDD!A$2:BR$570,49,FALSE) -> 45807
W40: =BBDD!AX1 -> BONOS | Y40: =VLOOKUP(D$4,BBDD!A$2:BR$570,50,FALSE) -> #N/A
W42: =BBDD!AY1 -> INCIDENCIA DE PAGOS | Y42: =VLOOKUP(D$4,BBDD!A$2:BR$570,51,FALSE) -> #N/A
W44: =BBDD!AZ1 -> SERV GASTRONOMICOS | Y44: =VLOOKUP(D$4,BBDD!A$2:BR$570,52,FALSE) -> #N/A
W46: =BBDD!BA1 -> GERENCIA/GRANDES CUENTAS | Y46: =VLOOKUP(D$4,BBDD!A$2:BR$570,53,FALSE) -> #N/A
W48: =BBDD!BB1 -> SYS INFORMES/SEGUROS | Y48: =VLOOKUP(D$4,BBDD!A$2:BR$570,54,FALSE) -> #N/A
W50: =BBDD!BC1 -> ANAC | Y50: =VLOOKUP(D$4,BBDD!A$2:BR$570,55,FALSE) -> #N/A
W52: =BBDD!BD1 -> EBONOS | Y52: =VLOOKUP(D$4,BBDD!A$2:BR$570,56,FALSE) -> #N/A
W54: =BBDD!BE1 -> MACROS | Y54: =VLOOKUP(D$4,BBDD!A$2:BR$570,57,FALSE) -> #N/A
W56: =BBDD!BF1 -> EQUIPO DE BUSQUEDA | Y56: =VLOOKUP(D$4,BBDD!A$2:BR$570,58,FALSE) -> #N/A

Sheet BBDD
A1: orden | B1: ID | C1: ID_BOOST | D1: DNI | E1: NOMBRE | F1: TLF | G1: ILT/MAT/EXC | H1: SERVICIO | I1: CATEGORIA | J1: SEGMENTO | K1: IDIOMA 1 | L1: ANTIGÜEDAD | M1: TM | N1: SERVICIO | O1: 20251222 | P1: 20251223 | Q1: 20251224 | R1: 20251225 | S1: 20251226 | T1: 20251227 | U1: 20251228 | V1: HORARIO | W1: EMEA | X1: CORREO | Y1: LOGIN | Z1: EXTENSION | AA1: USER SITEL | AB1: SALESFORCE | AC1: CALLCENTER | AD1: RESIBER | AE1: AMADEUS | AF1: DESKTOP | AG1: USER SYR | AH1: LLAMADAS | AI1: ASIGNACION | AJ1: BO EQUIPAJE | AK1: BO PASAJE | AL1: VIP | AM1: REDES/PRENSA | AN1: RPM | AO1: INFINITA | AP1: OW/AJB | AQ1: ATENCION PERSONAL/FELICITACIONES/SUGERENCIA/AGRADECIMIENTO | AR1: PMR/LESIONADOS/INTOX | AS1: TASAS CHILE | AT1: FUTUROS VUELOS | AU1: YQ | AV1: REEMBOLSOS PARCIAL Y TARIFA | AW1: REEMBOLSO TOTAL | AX1: BONOS | AY1: INCIDENCIA DE PAGOS | AZ1: SERV GASTRONOMICOS | BA1: GERENCIA/GRANDES CUENTAS | BB1: SYS INFORMES/SEGUROS | BC1: ANAC | BD1: EBONOS | BE1: MACROS | BF1: EQUIPO DE BUSQUEDA | BG1: ABIERTO A LA ESPERA | BH1: LIVECHAT | BI1: INCIVIA | BJ1: INSTRUCCIONES | BK1: DESKTOP | BL1: TRAIN ESTANDAR | BM1: ASIGNACION | BN1: ABOGADOS_EERR | BO1: DEMANDAS ESP | BP1: AESA | BQ1: OMICs | BR1: PAGOS ESPAÑA | BS1: ASIGNACION IDIOMA | BT1: TRAMITACION IDIOMA | BU1: SUDAMERICA ASGNACION | BV1: SUDAMERICA TRAMITACION | BW1: REEMBOLSOS JURIDICO | BX1: AVIACIÓN CIVIL (NO AESA) | BY1: ADR | BZ1: NORMATIVA DOT | CA1: TRAIN JURIDICO | CB1: TEC | CC1: CONTAR | CD1: PETICION | CE1: vb | CF1: PETICION | CG1: vb
A2: 1 | B2: 41U525 | C2: 9007573 | D2: 54184141M | E2: JUAN MANUEL SIVIANES SANTOS | F2: 608378208 | G2: NO | H2: SYR_ABOGADOS_ESPAÑOL | I2: AGENT | J2: JURÍDICO | K2: ESPAÑOL | L2: 45782 | M2: MARIA EMILIA ALEMAN NOCEA | O2: 15_21 | P2: LIBRA | Q2: 10_16 | R2: LFS_15_21 | S2: 15_21 | T2: 15_21 | U2: LIBRA | W2: jsivi005 | X2: jsivi005@ec.foundever.com | Y2: 3487003 | Z2: 3486651 | AB2: FOUND.JMSIVIANES | AC2: JMSILVIANS | AD2: 5143 | AE2: 5143JS | AF2: JMSIVIANES@525 | AH2: 45777 | AI2: 45777 | AJ2: 45777 | AK2: 45777 | AL2: #N/A | AM2: #N/A | AN2: #N/A | AO2: #N/A | AP2: #N/A | AQ2: #N/A | AR2: #N/A | AS2: #N/A | AT2: #N/A | AU2: #N/A | AV2: #N/A | AW2: 45777 | AX2: #N/A | AY2: #N/A | AZ2: #N/A | BA2: #N/A | BB2: #N/A | BC2: #N/A | BD2: #N/A | BE2: #N/A | BF2: #N/A | BG2: #N/A | BH2: #N/A | BI2: #N/A | BJ2: #N/A | BK2: 45953 | BM2: 45957 | BN2: 45957 | BO2: #N/A | BP2: #N/A | BQ2: #N/A | BR2: #N/A | BS2: #N/A | BT2: #N/A | BU2: #N/A | BV2: #N/A | BW2: #N/A | BX2: #N/A | BY2: #N/A | BZ2: #N/A | CB2: 45740 | CC2: 1 | CD2: 2025-01 | CF2: #N/A
A3: 2 | B3: 41U169 | C3: 9007140 | D3: 77817815Y | E3: BLANCA MONTERO MUÑOZ | F3: 637841107 | G3: NO | H3: SYR_ABOGADOS_ESPAÑOL | I3: AGENT | J3: JURÍDICO | K3: ESPAÑOL | L3: 45684 | M3: MARIA EMILIA ALEMAN NOCEA | O3: 12_20 | P3: 12_20 | Q3: 12_19 | R3: LFS_12_20 | S3: 12_20 | T3: LIBRA | U3: LIBRA | W3: bmont085 | X3: bmont085@ec.sitel.com | Y3: 3485935 | Z3: 3486490 | AB3: found.bmontero | AC3: BMONTERO | AD3: 5892M | AE3: 5892BM | AF3: BMONTERO@525 | AH3: 45684 | AI3: 45684 | AJ3: 45684 | AK3: 45684 | AL3: #N/A | AM3: #N/A | AN3: #N/A | AO3: #N/A | AP3: #N/A | AQ3: #N/A | AR3: #N/A | AS3: #N/A | AT3: #N/A | AU3: #N/A | AV3: #N/A | AW3: 45747 | AX3: #N/A | AY3: #N/A | AZ3: #N/A | BA3: #N/A | BB3: #N/A | BC3: #N/A | BD3: #N/A | BE3: #N/A | BF3: #N/A | BG3: #N/A | BH3: #N/A | BI3: #N/A | BJ3: #N/A | BK3: 45965 | BM3: 45957 | BN3: 45957 | BO3: #N/A | BP3: #N/A | BQ3: #N/A | BR3: #N/A | BS3: #N/A | BT3: #N/A | BU3: #N/A | BV3: #N/A | BW3: #N/A | BX3: #N/A | BY3: #N/A | BZ3: #N/A | CB3: #N/A | CC3: 1 | CD3: 2024-23 | CF3: 2025-22
A4: 3 | B4: 41S519 | C4: 1792216 | D4: 70816980A | E4: MARIA DE LA VEGA GARCIA BLAZQUEZ | F4: 646943214 | G4: NO | H4: SYR_ABOGADOS_ESPAÑOL | I4: AGENT | J4: JURÍDICO | K4: ESPAÑOL | L4: 45275 | M4: MARIA EMILIA ALEMAN NOCEA | O4: 14_22 | P4: 14_22 | Q4: VAC_15_21 | R4: VAC_15_21 | S4: VAC_15_21 | T4: VAC_LIBRA | U4: VAC_LIBRA | W4: mgarc1028 | X4: mgarc1028@ec.sitel.com | Y4: 3485888 | Z4: 3486459 | AB4: SITEL.MVGARCIA | AC4: VGBLAZQUEZ | AD4: 4561 | AE4: 4561MD | AF4: MVGARCIA@525 | AH4: 45274 | AI4: 45359 | AJ4: 45274 | AK4: 45359 | AL4: #N/A | AM4: #N/A | AN4: #N/A | AO4: #N/A | AP4: #N/A | AQ4: #N/A | AR4: #N/A | AS4: #N/A | AT4: #N/A | AU4: #N/A | AV4: #N/A | AW4: 45757 | AX4: #N/A | AY4: #N/A | AZ4: #N/A | BA4: #N/A | BB4: #N/A | BC4: #N/A | BD4: #N/A | BE4: #N/A | BF4: #N/A | BG4: #N/A | BH4: #N/A | BI4: #N/A | BJ4: #N/A | BK4: 45950 | BM4: 45957 | BN4: 45957 | BO4: #N/A | BP4: #N/A | BQ4: #N/A | BR4: #N/A | BS4: #N/A | BT4: #N/A | BU4: #N/A | BV4: #N/A | BW4: #N/A | BX4: #N/A | BY4: #N/A | BZ4: #N/A | CB4: 45734 | CC4: 1 | CD4: 2023-25 | CF4: 2025-22
A5: 4 | B5: 41T444 | C5: 1888366 | D5: 45996545H | E5: FRANCISCO JAVIER PARRADO PECELLIN | F5: 651333188 | G5: NO | H5: SYR_ABOGADOS_ESPAÑOL | I5: AGENT | J5: JURÍDICO | K5: ESPAÑOL | L5: 45490 | M5: MARIA EMILIA ALEMAN NOCEA | O5: 15_21 | P5: LIBRA | Q5: 15_21 | R5: LFS_15_21 | S5: 15_21 | T5: 15_21 | U5: LIBRA | W5: fparr021 | X5: fparr021@ec.sitel.com | Y5: 3485719 | Z5: 3486662 | AB5: SITEL.FJPARRADO | AC5: FJAVIPP | AD5: 5477 | AE5: 5477FP | AF5: FJPARRADO@525 | AH5: 45506 | AI5: 45506 | AJ5: 45506 | AK5: 45506 | AL5: #N/A | AM5: #N/A | AN5: #N/A | AO5: #N/A | AP5: #N/A | AQ5: #N/A | AR5: #N/A | AS5: #N/A | AT5: #N/A | AU5: #N/A | AV5: #N/A | AW5: 45586 | AX5: #N/A | AY5: #N/A | AZ5: #N/A | BA5: #N/A | BB5: #N/A | BC5: #N/A | BD5: #N/A | BE5: #N/A | BF5: #N/A | BG5: #N/A | BH5: #N/A | BI5: #N/A | BJ5: #N/A | BK5: 45953 | BM5: 45957 | BN5: 45957 | BO5: #N/A | BP5: #N/A | BQ5: #N/A | BR5: #N/A | BS5: #N/A | BT5: #N/A | BU5: #N/A | BV5: #N/A | BW5: #N/A | BX5: #N/A | BY5: #N/A | BZ5: #N/A | CB5: 45729 | CC5: 1 | CD5: 2024-13 | CF5: 2025-22
A6: 5 | B6: 41T590 | C6: 9006305 | D6: 29498081Y | E6: ANGELA CASTAÑEDA REINA | F6: 641019070 | G6: NO | H6: SYR_ABOGADOS_ESPAÑOL | I6: AGENT | J6: JURÍDICO | K6: ESPAÑOL | L6: 45532 | M6: LAURA HERRERA RODRIGUEZ | O6: 14_20 | P6: 14_20 | Q6: 14_20 | R6: 14_20 | S6: 14_20 | T6: LIBRA | U6: LIBRA | W6: acast695 | X6: acast695@ec.sitel.com | Y6: 3487024 | Z6: 3481528 | AB6: SITEL.ACASTANEDA | AC6: ACASREINA | AD6: 26097 | AE6: 6097AC | AF6: ACASTANEDA@525 | AH6: 45547 | AI6: 45547 | AJ6: 45547 | AK6: 45547 | AL6: #N/A | AM6: #N/A | AN6: #N/A | AO6: #N/A | AP6: #N/A | AQ6: #N/A | AR6: #N/A | AS6: #N/A | AT6: #N/A | AU6: #N/A | AV6: #N/A | AW6: 45643 | AX6: #N/A | AY6: #N/A | AZ6: #N/A | BA6: #N/A | BB6: #N/A | BC6: #N/A | BD6: #N/A | BE6: #N/A | BF6: #N/A | BG6: #N/A | BH6: #N/A | BI6: #N/A | BJ6: #N/A | BK6: 45982 | BM6: 45931 | BN6: 45931 | BO6: 45938 | BP6: #N/A | BQ6: #N/A | BR6: 45986 | BS6: #N/A | BT6: #N/A | BU6: #N/A | BV6: #N/A | BW6: #N/A | BX6: #N/A | BY6: #N/A | BZ6: #N/A | CB6: 45729 | CC6: 1 | CD6: 2024-18 | CF6: 2025-22
A7: 6 | B7: 41T650 | C7: 9006416 | D7: 49033182B | E7: ARIADNA ARQUELLADA MORALES | F7: 646391143 | G7: NO | H7: SYR_ABOGADOS_ESPAÑOL | I7: AGENT | J7: JURÍDICO | K7: ESPAÑOL | L7: 45544 | M7: LAURA HERRERA RODRIGUEZ | O7: 13_21 | P7: LIBRA | Q7: 13_21 | R7: 13_21 | S7: 13_21 | T7: 13_21 | U7: LIBRA | W7: aarqu007 | X7: aarqu007@ec.sitel.com | Y7: 3485862 | Z7: 3486478 | AB7: sitel.aarquellad | AC7: ARQUELLADAM | AD7: 26145 | AE7: 6145AA | AF7: AARQUELLAD@525 | AH7: 45560 | AI7: 45560 | AJ7: 45560 | AK7: 45560 | AL7: #N/A | AM7: #N/A | AN7: #N/A | AO7: #N/A | AP7: #N/A | AQ7: #N/A | AR7: #N/A | AS7: #N/A | AT7: #N/A | AU7: #N/A | AV7: #N/A | AW7: 45744 | AX7: #N/A | AY7: #N/A | AZ7: #N/A | BA7: #N/A | BB7: #N/A | BC7: #N/A | BD7: #N/A | BE7: #N/A | BF7: #N/A | BG7: #N/A | BH7: #N/A | BI7: #N/A | BJ7: #N/A | BK7: 45964 | BM7: 45931 | BN7: 45931 | BO7: 45938 | BP7: #N/A | BQ7: #N/A | BR7: 45986 | BS7: #N/A | BT7: #N/A | BU7: #N/A | BV7: #N/A | BW7: #N/A | BX7: #N/A | BY7: #N/A | BZ7: #N/A | CB7: 45729 | CC7: 1 | CD7: 2024-19 | CF7: 2025-22
A8: 7 | B8: 41R522 | C8: 1692286 | D8: 47345918G | E8: ANA OROPESA BARRERA | F8: 691202008 | G8: NO | H8: SYR_ABOGADOS_ESPAÑOL_WH | I8: AGENT | J8: JURÍDICO | K8: ESPAÑOL | L8: 45063 | M8: MIGUEL CASTILLO LIMON | O8: 12_20 | P8: LIBRA | Q8: 12_20 | R8: LFS_12_20 | S8: @SSYRABESP_12_20 | T8: @SSYRABESP_12_20 | U8: LIBRA | W8: aorop006 | X8: aorop006@ec.sitel.com | Y8: 3485608 | Z8: 3481416 | AB8: SITEL.aoropesa | AC8: AOROPESA | AD8: 4599 | AE8: 4599AO | AF8: AOROPESA@525 | AH8: 45062 | AI8: 45062 | AJ8: 45062 | AK8: 45062 | AL8: #N/A | AM8: #N/A | AN8: #N/A | AO8: #N/A | AP8: #N/A | AQ8: #N/A | AR8: #N/A | AS8: #N/A | AT8: #N/A | AU8: #N/A | AV8: #N/A | AW8: 45684 | AX8: #N/A | AY8: 45175 | AZ8: #N/A | BA8: #N/A | BB8: #N/A | BC8: #N/A | BD8: #N/A | BE8: #N/A | BF8: #N/A | BG8: #N/A | BH8: #N/A | BI8: #N/A | BJ8: #N/A | BK8: 45958 | BM8: 45812 | BN8: 45812 | BO8: #N/A | BP8: #N/A | BQ8: #N/A | BR8: #N/A | BS8: #N/A | BT8: #N/A | BU8: #N/A | BV8: #N/A | BW8: #N/A | BX8: #N/A | BY8: #N/A | BZ8: #N/A | CB8: #N/A | CC8: 1 | CD8: 2023-07 | CF8: 2025-22
A9: 8 | B9: 41T832 | C9: 9006617 | D9: 47538230J | E9: ANTONIO MESA ORTEGA | F9: 674085275 | G9: NO | H9: SYR_ABOGADOS_ESPAÑOL_WH | I9: AGENT | J9: JURÍDICO | K9: ESPAÑOL | L9: 45579 | M9: MIGUEL CASTILLO LIMON | O9: LIBRA | P9: @SSYRABESP_14_21 | Q9: 14_21 | R9: LFS_14_21 | S9: @SSYRABESP_14_21 | T9: @SSYRABESP_14_21 | U9: LIBRA | W9: amesa037 | X9: amesa037@ec.sitel.com | Y9: 3485801 | Z9: 3486670 | AB9: sitel.amesa | AC9: AMESA | AD9: 5067 | AE9: 5067AM | AF9: AMESA@525 | AH9: 45579 | AI9: 45579 | AJ9: 45579 | AK9: 45579 | AL9: #N/A | AM9: #N/A | AN9: #N/A | AO9: #N/A | AP9: #N/A | AQ9: #N/A | AR9: #N/A | AS9: #N/A | AT9: #N/A | AU9: 45923 | AV9: 45734 | AW9: 45700 | AX9: #N/A | AY9: #N/A | AZ9: #N/A | BA9: #N/A | BB9: #N/A | BC9: #N/A | BD9: #N/A | BE9: #N/A | BF9: #N/A | BG9: #N/A | BH9: #N/A | BI9: #N/A | BJ9: #N/A | BK9: 45973 | BM9: 45812 | BN9: 45812 | BO9: 45937 | BP9: #N/A | BQ9: #N/A | BR9: 45971 | BS9: 45812 | BT9: #N/A | BU9: #N/A | BV9: #N/A | BW9: #N/A | BX9: #N/A | BY9: #N/A | BZ9: #N/A | CB9: #N/A | CC9: 1 | CD9: 2024-20 | CF9: 2025-22
A10: 9 | B10: 41S643 | C10: 1801673 | D10: 73004180H | E10: MARCO ANDRES RANCAÑO | F10: 628090609 | G10: NO | H10: SYR_ABOGADOS_ESPAÑOL_WH | I10: AGENT | J10: JURÍDICO | K10: ESPAÑOL | L10: 45327 | M10: PATRICIA MARTINEZ ALONSO | O10: 08_16 | P10: 08_16 | Q10: 08_16 | R10: 08_16 | S10: 08_16 | T10: LIBRA | U10: LIBRA | W10: mandr183 | X10: mandr183@ec.sitel.com | Y10: 3485728 | Z10: 3486352 | AB10: SITEL.mandres | AC10: MRANCANO | AD10: 27591 | AE10: 7591MR | AF10: MANDRES@525 | AH10: 45492 | AI10: 45492 | AJ10: 45492 | AK10: 45492 | AL10: #N/A | AM10: #N/A | AN10: #N/A | AO10: #N/A | AP10: #N/A | AQ10: #N/A | AR10: #N/A | AS10: #N/A | AT10: 45492 | AU10: #N/A | AV10: #N/A | AW10: 45677 | AX10: #N/A | AY10: #N/A | AZ10: #N/A | BA10: #N/A | BB10: #N/A | BC10: #N/A | BD10: #N/A | BE10: #N/A | BF10: #N/A | BG10: #N/A | BH10: #N/A | BI10: #N/A | BJ10: #N/A | BK10: 45978 | BM10: 45812 | BN10: 45812 | BO10: 45937 | BP10: #N/A | BQ10: #N/A | BR10: #N/A | BS10: 45812 | BT10: #N/A | BU10: #N/A | BV10: #N/A | BW10: #N/A | BX10: #N/A | BY10: #N/A | BZ10: #N/A | CB10: 45723 | CC10: 1 | CD10: 2024-11 | CF10: 2025-22
A11: 10 | B11: 41T431 | C11: 1888352 | D11: 49192172W | E11: MARIA DE LAS CASAS LEON | F11: 682725170 | G11: NO | H11: SYR_ABOGADOS_ESPAÑOL_WH | I11: AGENT | J11: JURÍDICO | K11: ESPAÑOL | L11: 45490 | M11: LAURA HERRERA RODRIGUEZ | O11: 12_20 | P11: 13_20 | Q11: VAC_12_20 | R11: LFS_12_20 | S11: 12_20 | T11: LIBRA | U11: LIBRA | W11: mdela599 | X11: mdela599@ec.sitel.com | Y11: 3485185 | Z11: 3486495 | AB11: SITEL.mcasas | AC11: MARIADCAL | AD11: 5302 | AE11: 5302MD | AF11: MCASAS@525 | AH11: 45506 | AI11: 45506 | AJ11: 45506 | AK11: 45506 | AL11: #N/A | AM11: #N/A | AN11: #N/A | AO11: #N/A | AP11: #N/A | AQ11: #N/A | AR11: #N/A | AS11: #N/A | AT11: #N/A | AU11: #N/A | AV11: #N/A | AW11: 45625 | AX11: #N/A | AY11: #N/A | AZ11: #N/A | BA11: #N/A | BB11: #N/A | BC11: #N/A | BD11: #N/A | BE11: #N/A | BF11: #N/A | BG11: #N/A | BH11: #N/A | BI11: #N/A | BJ11: #N/A | BK11: 46001 | BM11: 45931 | BN11: 45931 | BO11: 45938 | BP11: #N/A | BQ11: #N/A | BR11: #N/A | BS11: #N/A | BT11: #N/A | BU11: #N/A | BV11: #N/A | BW11: #N/A | BX11: #N/A | BY11: #N/A | BZ11: #N/A | CB11: #N/A | CC11: 1 | CD11: 2024-13 | CF11: #N/A
A12: 11 | B12: 41T443 | C12: 1888365 | D12: 29533645N | E12: LAURA PALOMINO FERNANDEZ | F12: 654859682 | G12: NO | H12: SYR_ABOGADOS_ESPAÑOL_WH | I12: AGENT | J12: JURÍDICO | K12: ESPAÑOL | L12: 45490 | M12: FABIO GREGORI | O12: VAC_15_21 | P12: VAC_15_21 | Q12: VAC_15_21 | R12: VAC_15_21 | S12: VAC_15_21 | T12: VAC_LIBRA | U12: VAC_LIBRA | W12: lpalo025 | X12: lpalo025@ec.sitel.com | Y12: 3485394 | Z12: 3486467 | AB12: SITEL.LPALOMINO | AC12: LAURPALF | AD12: 5325 | AE12: 5325LP | AF12: LPALOMINO@525 | AH12: 45506 | AI12: 45506 | AJ12: 45506 | AK12: 45506 | AL12: #N/A | AM12: #N/A | AN12: #N/A | AO12: #N/A | AP12: #N/A | AQ12: #N/A | AR12: #N/A | AS12: #N/A | AT12: #N/A | AU12: #N/A | AV12: #N/A | AW12: 45625 | AX12: #N/A | AY12: #N/A | AZ12: #N/A | BA12: #N/A | BB12: #N/A | BC12: #N/A | BD12: #N/A | BE12: #N/A | BF12: #N/A | BG12: #N/A | BH12: #N/A | BI12: #N/A | BJ12: #N/A | BK12: 46001 | BM12: 45957 | BN12: 45957 | BO12: #N/A | BP12: #N/A | BQ12: #N/A | BR12: #N/A | BS12: #N/A | BT12: #N/A | BU12: #N/A | BV12: #N/A | BW12: #N/A | BX12: #N/A | BY12: #N/A | BZ12: #N/A | CB12: 45734 | CC12: 1 | CD12: 2024-13 | CF12: #N/A
A13: 12 | B13: 41T471 | C13: 1890123 | D13: 47545326W | E13: MARIA SANCHEZ GALVEZ | F13: 679528741 | G13: NO | H13: SYR_ABOGADOS_ESPAÑOL_WH | I13: AGENT | J13: JURÍDICO | K13: ESPAÑOL | L13: 45502 | M13: LAURA HERRERA RODRIGUEZ | O13: 15_21 | P13: 15_21 | Q13: 10_16 | R13: LFS_15_21 | S13: 15_21 | T13: LIBRA | U13: LIBRA | W13: msanc629 | X13: msanc629@ec.sitel.com | Y13: 3485941 | Z13: 3481195 | AB13: SITEL.MSANCHEZG | AC13: MSANCHEZGALV | AD13: 5656 | AE13: 5656MS | AF13: MSANCHEZG@525 | AH13: 45514 | AI13: 45514 | AJ13: 45514 | AK13: 45514 | AL13: #N/A | AM13: #N/A | AN13: #N/A | AO13: #N/A | AP13: #N/A | AQ13: #N/A | AR13: #N/A | AS13: #N/A | AT13: #N/A | AU13: #N/A | AV13: #N/A | AW13: 45694 | AX13: #N/A | AY13: #N/A | AZ13: #N/A | BA13: #N/A | BB13: #N/A | BC13: #N/A | BD13: #N/A | BE13: #N/A | BF13: #N/A | BG13: #N/A | BH13: #N/A | BI13: #N/A | BJ13: #N/A | BK13: 45953 | BM13: 45957 | BN13: 45957 | BO13: #N/A | BP13: #N/A | BQ13: #N/A | BR13: #N/A | BS13: #N/A | BT13: #N/A | BU13: #N/A | BV13: #N/A | BW13: #N/A | BX13: #N/A | BY13: #N/A | BZ13: #N/A | CB13: #N/A | CC13: 1 | CD13: 2024-14 | CF13: #N/A
A14: 13 | B14: 417775 | C14: 9000724 | D14: 20799486B | E14: ELIZABETH GARCIA OCHERA | F14: 657995848 | G14: NO | H14: SYR_ABOGADOS_ESPAÑOL_WH | I14: AGENT | J14: JURÍDICO | K14: ESPAÑOL | L14: 39135 | M14: OSCAR EDUARDO CAÑIZALEZ PEREZ | O14: 14_20 | P14: 14_20 | Q14: 14_20 | R14: LFS_14_20 | S14: 14_20 | T14: LIBRA | U14: LIBRA | W14: egarc011 | X14: egarc011@ec.sitel.com | Y14: 3485633 | Z14: 3486261 | AB14: sitel.egarciao | AC14: EGARCI | AD14: 4340 | AE14: 4340EG | AF14: EGARCIAO@525 | AH14: 44641 | AI14: 44641 | AJ14: 44641 | AK14: 44641 | AL14: #N/A | AM14: 45245 | AN14: #N/A | AO14: #N/A | AP14: #N/A | AQ14: #N/A | AR14: 45246 | AS14: #N/A | AT14: #N/A | AU14: #N/A | AV14: #N/A | AW14: 45744 | AX14: #N/A | AY14: #N/A | AZ14: #N/A | BA14: #N/A | BB14: #N/A | BC14: #N/A | BD14: #N/A | BE14: #N/A | BF14: #N/A | BG14: #N/A | BH14: #N/A | BI14: #N/A | BJ14: #N/A | BK14: 46002 | BM14: #N/A | BN14: #N/A | BO14: #N/A | BP14: #N/A | BQ14: #N/A | BR14: #N/A | BS14: #N/A | BT14: #N/A | BU14: #N/A | BV14: #N/A | BW14: #N/A | BX14: #N/A | BY14: #N/A | BZ14: #N/A | CB14: 45734 | CC14: 1 | CD14: #N/A | CF14: #N/A
A15: 14 | B15: 416397 | C15: 9001093 | D15: 44953114M | E15: BEATRIZ URBINA LAVIN | F15: 608678427 | G15: NO | H15: SYR_ABOGADOS_ESPAÑOL_WH | I15: AGENT | J15: JURÍDICO | K15: ESPAÑOL | L15: 42621 | M15: OSCAR EDUARDO CAÑIZALEZ PEREZ | O15: 15_23 | P15: 15_22 | Q15: VAC_15_23 | R15: VAC_15_23 | S15: VAC_15_23 | T15: VAC_LIBRA | U15: VAC_LIBRA | W15: burbi002 | X15: burbi002@ec.sitel.com | Y15: 3485253 | Z15: 3481207 | AB15: SITEL.burbina | AC15: BURBINAL | AD15: 26238U | AE15: 6238BU | AF15: 0 | AH15: 45448 | AI15: 45448 | AJ15: 45448 | AK15: 45448 | AL15: #N/A | AM15: #N/A | AN15: #N/A | AO15: #N/A | AP15: #N/A | AQ15: #N/A | AR15: #N/A | AS15: #N/A | AT15: #N/A | AU15: #N/A | AV15: #N/A | AW15: 45679 | AX15: #N/A | AY15: #N/A | AZ15: #N/A | BA15: #N/A | BB15: #N/A | BC15: #N/A | BD15: #N/A | BE15: #N/A | BF15: #N/A | BG15: #N/A | BH15: #N/A | BI15: #N/A | BJ15: #N/A | BK15: #N/A | BM15: #N/A | BN15: #N/A | BO15: #N/A | BP15: #N/A | BQ15: #N/A | BR15: #N/A | BS15: #N/A | BT15: #N/A | BU15: #N/A | BV15: #N/A | BW15: #N/A | BX15: #N/A | BY15: #N/A | BZ15: #N/A | CB15: #N/A | CC15: 1 | CD15: #N/A | CF15: #N/A
A16: 15 | B16: 41T905 | C16: 9006751 | D16: 77817313X | E16: ANA CRISTINA DIAZ ROBLES | F16: 637122222 | G16: NO | H16: SYR_ABOGADOS_ESPAÑOL_WH | I16: AGENT | J16: JURÍDICO | K16: ESPAÑOL | L16: 45600 | M16: OSCAR EDUARDO CAÑIZALEZ PEREZ | O16: LIBRA | P16: @SSYRABESP_15_21 | Q16: 15_21 | R16: 15_21 | S16: @SSYRABESP_15_21 | T16: @SSYRABESP_15_21 | U16: LIBRA | W16: adiaz349 | X16: adiaz349@ec.sitel.com | Y16: 3485995 | Z16: 3486738 | AB16: sitel.acdiaz | AC16: ANACRISDIA | AD16: 5648 | AE16: 5648AD | AF16: 0 | AH16: 45589 | AI16: 45600 | AJ16: 45600 | AK16: 45600 | AL16: 45875 | AM16: #N/A | AN16: #N/A | AO16: 30/09/2025@ | AP16: #N/A | AQ16: 45875 | AR16: #N/A | AS16: #N/A | AT16: #N/A | AU16: #N/A | AV16: #N/A | AW16: 45737 | AX16: #N/A | AY16: #N/A | AZ16: #N/A | BA16: #N/A | BB16: #N/A | BC16: #N/A | BD16: #N/A | BE16: #N/A | BF16: #N/A | BG16: #N/A | BH16: #N/A | BI16: #N/A | BJ16: #N/A | BK16: #N/A | BM16: #N/A | BN16: #N/A | BO16: #N/A | BP16: #N/A | BQ16: #N/A | BR16: #N/A | BS16: #N/A | BT16: #N/A | BU16: #N/A | BV16: #N/A | BW16: #N/A | BX16: #N/A | BY16: #N/A | BZ16: #N/A | CB16: 45729 | CC16: 1 | CD16: 2024-23 | CF16: #N/A
A17: 16 | B17: 41E071 | C17: 9001541 | D17: 44609195M | E17: MARIA JOSE FERNANDEZ MORENO | F17: 692153887 | G17: NO | H17: SYR_ABOGADOS_ESPAÑOL_WH | I17: AGENT | J17: JURÍDICO | K17: ESPAÑOL | L17: 41774 | M17: NIKOLAY NAZAROV | O17: 08_1430 | P17: 08_1430 | Q17: 08_1430 | R17: LFS_08_1430 | S17: 08_1430 | T17: LIBRA | U17: LIBRA | W17: mfern324 | X17: mfern324@ec.sitel.com | Y17: 3485439 | Z17: 3481266 | AB17: sitel.mjfernande | AC17: MJFERENANDEZ | AD17: 27700 | AE17: 27700MF | AF17: MJFERNANDE@525 | AH17: 44817 | AI17: 44817 | AJ17: 44817 | AK17: 45057 | AL17: #N/A | AM17: #N/A | AN17: #N/A | AO17: #N/A | AP17: #N/A | AQ17: #N/A | AR17: #N/A | AS17: #N/A | AT17: #N/A | AU17: #N/A | AV17: #N/A | AW17: 45677 | AX17: #N/A | AY17: #N/A | AZ17: #N/A | BA17: #N/A | BB17: #N/A | BC17: #N/A | BD17: #N/A | BE17: #N/A | BF17: #N/A | BG17: #N/A | BH17: #N/A | BI17: #N/A | BJ17: #N/A | BK17: 45982 | BM17: 45931 | BN17: 45931 | BO17: 45938 | BP17: #N/A | BQ17: #N/A | BR17: #N/A | BS17: #N/A | BT17: #N/A | BU17: #N/A | BV17: #N/A | BW17: #N/A | BX17: #N/A | BY17: #N/A | BZ17: #N/A | CB17: 45726 | CC17: 1 | CD17: 2022-22 | CF17: #N/A
A18: 17 | B18: 41T830 | C18: 9006615 | D18: 54180074D | E18: MARIA DEL ROCIO GOMEZ GONZALEZ | F18: 644341026 | G18: NO | H18: SYR_ABOGADOS_ESPAÑOL_WH | I18: AGENT | J18: JURÍDICO | K18: ESPAÑOL | L18: 45579 | M18: MARIA EMILIA ALEMAN NOCEA | O18: LIBRA | P18: 15_22 | Q18: 14_21 | R18: LFS_15_22 | S18: 15_22 | T18: 10_17 | U18: LIBRA | W18: mgome471 | X18: mgome471@ec.sitel.com | Y18: 3485983 | Z18: 3481551 | AB18: sitel.mrgomez | AC18: RGOMEZG | AD18: 5899 | AE18: 5899MG | AF18: MRGOMEZ@525 | AH18: 45579 | AI18: 45579 | AJ18: 45579 | AK18: 45579 | AL18: #N/A | AM18: #N/A | AN18: #N/A | AO18: #N/A | AP18: #N/A | AQ18: #N/A | AR18: #N/A | AS18: #N/A | AT18: #N/A | AU18: #N/A | AV18: 45734 | AW18: 45698 | AX18: #N/A | AY18: #N/A | AZ18: #N/A | BA18: #N/A | BB18: #N/A | BC18: #N/A | BD18: #N/A | BE18: #N/A | BF18: #N/A | BG18: #N/A | BH18: #N/A | BI18: #N/A | BJ18: #N/A | BK18: 45973 | BM18: 45957 | BN18: 45957 | BO18: #N/A | BP18: #N/A | BQ18: #N/A | BR18: #N/A | BS18: #N/A | BT18: #N/A | BU18: #N/A | BV18: #N/A | BW18: #N/A | BX18: #N/A | BY18: #N/A | BZ18: #N/A | CB18: #N/A | CC18: 1 | CD18: 2024-20 | CF18: #N/A
A19: 18 | B19: 41T505 | C19: 1891134 | D19: X7564112X | E19: FLORINA ALEXANDRA BOGDAN | F19: 642908493 | G19: NO | H19: SYR_ABOGADOS_INGLES | I19: AGENT | J19: JURÍDICO | K19: INGLÉS | L19: 45505 | M19: MIGUEL CASTILLO LIMON | O19: 12_20 | P19: 13_20 | Q19: 12_19 | R19: LFS_12_20 | S19: 13_20 | T19: LIBRA | U19: LIBRA | W19: fbogd003 | X19: fbogd003@ec.sitel.com | Y19: 3485721 | Z19: 3486360 | AB19: SITEL.fbogdan | AC19: FLORINABOG | AD19: 5182 | AE19: 5182FB | AF19: FBOGDAN@525 | AH19: 45523 | AI19: 45523 | AJ19: 45523 | AK19: 45523 | AL19: 45600 | AM19: 45600 | AN19: 04/11/2024@ | AO19: #N/A | AP19: #N/A | AQ19: #N/A | AR19: #N/A | AS19: #N/A | AT19: #N/A | AU19: 45912 | AV19: 45734 | AW19: 45694 | AX19: #N/A | AY19: #N/A | AZ19: #N/A | BA19: #N/A | BB19: #N/A | BC19: #N/A | BD19: #N/A | BE19: #N/A | BF19: #N/A | BG19: #N/A | BH19: #N/A | BI19: #N/A | BJ19: #N/A | BK19: 45973 | BM19: 45812 | BN19: 45812 | BO19: 46006 | BP19: #N/A | BQ19: 45929 | BR19: #N/A | BS19: 45812 | BT19: #N/A | BU19: #N/A | BV19: #N/A | BW19: #N/A | BX19: 45979 | BY19: #N/A | BZ19: #N/A | CB19: #N/A | CC19: 1 | CD19: 2024-15 | CF19: #N/A
A20: 19 | B20: 41T392 | C20: 1888639 | D20: 18558406M | E20: MARCELA ALEXANDRA BORREGO MERINO | F20: 613830821 | G20: NO | H20: SYR_ABOGADOS_INGLES | I20: AGENT | J20: JURÍDICO | K20: INGLÉS | L20: 45481 | M20: NIKOLAY NAZAROV | O20: LFC_15_22 | P20: 15_22 | Q20: 15_22 | R20: LFS_15_22 | S20: 15_22 | T20: 07_14 | U20: LIBRA | W20: mborr047 | X20: mborr047@ec.sitel.com | Y20: 3485890 | Z20: 3486583 | AB20: sitel.maborrego | AC20: MARBORMER | AD20: 5357 | AE20: 5357MB | AF20: MABORREGO@525 | AH20: 45497 | AI20: 45497 | AJ20: 45497 | AK20: 45497 | AL20: #N/A | AM20: #N/A | AN20: #N/A | AO20: #N/A | AP20: #N/A | AQ20: #N/A | AR20: #N/A | AS20: #N/A | AT20: #N/A | AU20: #N/A | AV20: #N/A | AW20: 45742 | AX20: #N/A | AY20: #N/A | AZ20: #N/A | BA20: #N/A | BB20: #N/A | BC20: #N/A | BD20: #N/A | BE20: #N/A | BF20: #N/A | BG20: #N/A | BH20: #N/A | BI20: #N/A | BJ20: #N/A | BK20: 45982 | BM20: 45862 | BN20: 45862 | BO20: #N/A | BP20: #N/A | BQ20: 45929 | BR20: #N/A | BS20: 45862 | BT20: #N/A | BU20: #N/A | BV20: #N/A | BW20: #N/A | BX20: #N/A | BY20: #N/A | BZ20: #N/A | CB20: #N/A | CC20: 1 | CD20: 2024-12 | CF20: #N/A
A21: 20 | B21: 41T549 | C21: 1893321 | D21: 32089134V | E21: SANDRA NUÑEZ CABALLERO | F21: 687504028 | G21: NO | H21: SYR_ABOGADOS_INGLES | I21: AGENT | J21: JURÍDICO | K21: INGLÉS | L21: 45516 | M21: NIKOLAY NAZAROV | O21: VAC_15_22 | P21: VAC_09_16 | Q21: VAC_15_22 | R21: VAC_09_16 | S21: 15_22 | T21: LIBRA | U21: LIBRA | W21: snune039 | X21: snune039@ec.sitel.com | Y21: 3487057 | Z21: 3481561 | AB21: SITEL.snunezc | AC21: SNUNEZ | AD21: 5335 | AE21: 5335SN | AF21: SNUNEZC@525 | AH21: 45531 | AI21: 45531 | AJ21: 45531 | AK21: 45531 | AL21: 45600 | AM21: 45600 | AN21: 04/11/2024@ | AO21: #N/A | AP21: #N/A | AQ21: #N/A | AR21: #N/A | AS21: #N/A | AT21: #N/A | AU21: #N/A | AV21: #N/A | AW21: 45679 | AX21: #N/A | AY21: #N/A | AZ21: #N/A | BA21: #N/A | BB21: #N/A | BC21: #N/A | BD21: #N/A | BE21: #N/A | BF21: #N/A | BG21: #N/A | BH21: #N/A | BI21: #N/A | BJ21: #N/A | BK21: 45954 | BM21: 45862 | BN21: 45862 | BO21: 45915 | BP21: #N/A | BQ21: 45929 | BR21: 45986 | BS21: 45862 | BT21: #N/A | BU21: #N/A | BV21: #N/A | BW21: #N/A | BX21: #N/A | BY21: #N/A | BZ21: #N/A | CB21: #N/A | CC21: 1 | CD21: 2024-16 | CF21: #N/A
A22: 21 | B22: 41M881 | C22: 9005703 | D22: 08896278Q | E22: JOSE GALVEZ CORTES | F22: 691239944 | G22: NO | H22: SYR_ABOGADOS_INGLES | I22: AGENT | J22: JURÍDICO | K22: INGLÉS | L22: 45464 | M22: PATRICIA MARTINEZ ALONSO | O22: VAC_08_15 | P22: VAC_08_15 | Q22: VAC_08_15 | R22: VAC_08_15 | S22: VAC_08_15 | T22: VAC_LIBRA | U22: VAC_LIBRA | W22: jgalv104 | X22: jgalv104@ec.sitel.com | Y22: 3485963 | Z22: 3486663 | AB22: sitel.jgalvez | AC22: JGALVEZC | AD22: 5348 | AE22: 5348JG | AF22: JGALVEZ@525 | AH22: 45481 | AI22: 45481 | AJ22: 45481 | AK22: 45481 | AL22: 45681 | AM22: #N/A | AN22: #N/A | AO22: #N/A | AP22: 45681 | AQ22: #N/A | AR22: #N/A | AS22: #N/A | AT22: #N/A | AU22: 45922 | AV22: 45734 | AW22: 45616 | AX22: #N/A | AY22: #N/A | AZ22: #N/A | BA22: #N/A | BB22: #N/A | BC22: #N/A | BD22: #N/A | BE22: #N/A | BF22: #N/A | BG22: #N/A | BH22: #N/A | BI22: #N/A | BJ22: #N/A | BK22: 45957 | BM22: 45862 | BN22: 45862 | BO22: 46006 | BP22: 45930 | BQ22: #N/A | BR22: #N/A | BS22: 45862 | BT22: #N/A | BU22: #N/A | BV22: #N/A | BW22: #N/A | BX22: #N/A | BY22: #N/A | BZ22: #N/A | CB22: #N/A | CC22: 1 | CD22: 2024-09 | CF22: #N/A
A23: 22 | B23: 41U173 | C23: 9007144 | D23: 26776033P | E23: HELENA RIVERO GIL | F23: 603018998 | G23: NO | H23: SYR_ABOGADOS_INGLES | I23: AGENT | J23: JURÍDICO | K23: INGLÉS | L23: 45684 | M23: LAURA HERRERA RODRIGUEZ | O23: 09_17 | P23: 09_16 | Q23: 09_17 | R23: LFS_09_17 | S23: 09_17 | T23: LIBRA | U23: LIBRA | W23: hrive040 | X23: hrive040@ec.sitel.com | Y23: 3487038 | Z23: 3486567 | AB23: found.hrivero | AC23: HRIVERO | AD23: 5838R | AE23: 5838HR | AF23: HRIVERO@525 | AH23: 45684 | AI23: 45684 | AJ23: 45684 | AK23: 45684 | AL23: #N/A | AM23: #N/A | AN23: #N/A | AO23: #N/A | AP23: #N/A | AQ23: #N/A | AR23: #N/A | AS23: #N/A | AT23: #N/A | AU23: #N/A | AV23: #N/A | AW23: 45756 | AX23: #N/A | AY23: #N/A | AZ23: #N/A | BA23: #N/A | BB23: #N/A | BC23: #N/A | BD23: #N/A | BE23: #N/A | BF23: #N/A | BG23: #N/A | BH23: #N/A | BI23: #N/A | BJ23: #N/A | BK23: 45973 | BM23: 45873 | BN23: 45873 | BO23: 45915 | BP23: #N/A | BQ23: 45929 | BR23: 45971 | BS23: 45979 | BT23: 45979 | BU23: #N/A | BV23: #N/A | BW23: #N/A | BX23: 45979 | BY23: #N/A | BZ23: #N/A | CB23: 45729 | CC23: 1 | CD23: 2024-23 | CF23: #N/A
A24: 23 | B24: 41U174 | C24: 9007145 | D24: 30217867F | E24: GAELLE ROBERT MANCERA | F24: 633567371 | G24: NO | H24: SYR_ABOGADOS_INGLES | I24: AGENT | J24: JURÍDICO | K24: INGLÉS | L24: 45684 | M24: LAURA HERRERA RODRIGUEZ | O24: 15_2130 | P24: 15_2130 | Q24: LIBRA | R24: LFS_15_2130 | S24: 15_2130 | T24: 15_2130 | U24: LIBRA | W24: grobe027 | X24: grobe027@ec.sitel.com | Y24: 3485848 | Z24: 3481535 | AB24: found.grobert | AC24: GROBERT | AD24: 5890M | AE24: 5890GM | AF24: GROBERT@525 | AH24: 45684 | AI24: 45684 | AJ24: 45684 | AK24: 45684 | AL24: #N/A | AM24: #N/A | AN24: #N/A | AO24: #N/A | AP24: #N/A | AQ24: #N/A | AR24: #N/A | AS24: #N/A | AT24: #N/A | AU24: #N/A | AV24: #N/A | AW24: 45754 | AX24: #N/A | AY24: #N/A | AZ24: #N/A | BA24: #N/A | BB24: #N/A | BC24: #N/A | BD24: #N/A | BE24: #N/A | BF24: #N/A | BG24: #N/A | BH24: #N/A | BI24: #N/A | BJ24: #N/A | BK24: 45964 | BM24: 45873 | BN24: 45873 | BO24: 45915 | BP24: #N/A | BQ24: 45929 | BR24: 45971 | BS24: #N/A | BT24: #N/A | BU24: #N/A | BV24: #N/A | BW24: #N/A | BX24: #N/A | BY24: #N/A | BZ24: #N/A | CB24: 45729 | CC24: 1 | CD24: 2024-23 | CF24: #N/A
A25: 24 | B25: 41S237 | C25: 1776323 | D25: 28843891M | E25: CLAUDIA SMITH GUTIERREZ | F25: 625509314 | G25: NO | H25: SYR_ABOGADOS_INGLES | I25: AGENT | J25: JURÍDICO | K25: INGLÉS | L25: 45217 | M25: LAURA HERRERA RODRIGUEZ | O25: 09_15 | P25: 09_15 | Q25: 09_15 | R25: 11_17 | S25: 09_15 | T25: LIBRA | U25: LIBRA | W25: csmit513 | X25: csmit513@ec.sitel.com | Y25: 3485853 | Z25: 3486379 | AB25: SITEL.csmith | AC25: CSMITH | AD25: 4468 | AE25: 4468CS | AF25: CSMITH@525 | AH25: 45210 | AI25: 45369 | AJ25: 45217 | AK25: 45369 | AL25: #N/A | AM25: #N/A | AN25: #N/A | AO25: #N/A | AP25: #N/A | AQ25: #N/A | AR25: #N/A | AS25: #N/A | AT25: #N/A | AU25: #N/A | AV25: #N/A | AW25: 45831 | AX25: #N/A | AY25: #N/A | AZ25: #N/A | BA25: #N/A | BB25: #N/A | BC25: #N/A | BD25: #N/A | BE25: #N/A | BF25: #N/A | BG25: #N/A | BH25: #N/A | BI25: #N/A | BJ25: #N/A | BK25: 45953 | BM25: 45931 | BN25: 45931 | BO25: 45938 | BP25: #N/A | BQ25: #N/A | BR25: #N/A | BS25: #N/A | BT25: #N/A | BU25: #N/A | BV25: #N/A | BW25: #N/A | BX25: #N/A | BY25: #N/A | BZ25: #N/A | CB25: #N/A | CC25: 1 | CD25: 2023-21 | CF25: #N/A
A26: 25 | B26: 41U687 | C26: 9007844 | D26: 30251448P | E26: PAULA COBO DEL OLMO | F26: 620716940 | G26: NO | H26: SYR_ABOGADOS_INGLES | I26: AGENT | J26: JURÍDICO | K26: INGLÉS | L26: 45824 | M26: MARIA EMILIA ALEMAN NOCEA | O26: 15_22 | P26: 15_22 | Q26: 15_22 | R26: LFS_15_22 | S26: 15_22 | T26: LIBRA | U26: LIBRA | W26: pcobo002 | X26: pcobo002@ec.foundever.com | Y26: 3485790 | Z26: 3481409 | AB26: found.pcobo | AC26: PAULACOBO | AD26: 5299 | AE26: 5299PC | AF26: PCOBO@525 | AH26: 45824 | AI26: 45824 | AJ26: 45824 | AK26: 45824 | AL26: #N/A | AM26: #N/A | AN26: #N/A | AO26: #N/A | AP26: #N/A | AQ26: #N/A | AR26: #N/A | AS26: #N/A | AT26: #N/A | AU26: #N/A | AV26: #N/A | AW26: 45819 | AX26: #N/A | AY26: #N/A | AZ26: #N/A | BA26: #N/A | BB26: #N/A | BC26: #N/A | BD26: #N/A | BE26: #N/A | BF26: #N/A | BG26: #N/A | BH26: #N/A | BI26: #N/A | BJ26: #N/A | BK26: 45954 | BM26: 45957 | BN26: 45957 | BO26: #N/A | BP26: #N/A | BQ26: #N/A | BR26: #N/A | BS26: #N/A | BT26: #N/A | BU26: #N/A | BV26: #N/A | BW26: #N/A | BX26: #N/A | BY26: #N/A | BZ26: #N/A | CB26: 45820 | CC26: 1 | CD26: 2025-07 | CF26: #N/A
A27: 26 | B27: 41U692 | C27: 9007848 | D27: 47555117H | E27: JOSE CARLOS SEVILLA DURAN | F27: 678190616 | G27: NO | H27: SYR_ABOGADOS_INGLES | I27: AGENT | J27: JURÍDICO | K27: INGLÉS | L27: 45824 | M27: MARIA EMILIA ALEMAN NOCEA | O27: 15_22 | P27: 15_22 | Q27: 15_22 | R27: 15_22 | S27: 15_22 | T27: LIBRA | U27: LIBRA | W27: jsevi066 | X27: jsevi066@ec.foundever.com | Y27: 3485511 | Z27: 3481382 | AB27: found.jcsevilla | AC27: JCARSEVI | AD27: 5074 | AE27: 5074JS | AF27: JCSEVILLA@525 | AH27: 45824 | AI27: 45824 | AJ27: 45824 | AK27: 45824 | AL27: #N/A | AM27: #N/A | AN27: #N/A | AO27: #N/A | AP27: #N/A | AQ27: #N/A | AR27: #N/A | AS27: #N/A | AT27: #N/A | AU27: #N/A | AV27: #N/A | AW27: 45819 | AX27: #N/A | AY27: #N/A | AZ27: #N/A | BA27: #N/A | BB27: #N/A | BC27: #N/A | BD27: #N/A | BE27: #N/A | BF27: #N/A | BG27: #N/A | BH27: #N/A | BI27: #N/A | BJ27: #N/A | BK27: 45964 | BM27: 45957 | BN27: 45957 | BO27: #N/A | BP27: #N/A | BQ27: #N/A | BR27: #N/A | BS27: #N/A | BT27: #N/A | BU27: #N/A | BV27: #N/A | BW27: #N/A | BX27: #N/A | BY27: #N/A | BZ27: #N/A | CB27: 45820 | CC27: 1 | CD27: 2025-07 | CF27: #N/A
A28: 27 | B28: 41U650 | C28: 9007722 | D28: 77850099K | E28: MARIA THIRIET CHAPARRO | F28: 672238177 | G28: NO | H28: SYR_ABOGADOS_INGLES | I28: AGENT | J28: JURÍDICO | K28: INGLÉS | L28: 45810 | M28: MARIA EMILIA ALEMAN NOCEA | O28: 14_22 | P28: 14_22 | Q28: 14_21 | R28: LFS_14_22 | S28: 14_22 | T28: LIBRA | U28: LIBRA | W28: mthir009 | X28: mthir009@ec.foundever.com | Y28: 3485921 | Z28: 3486425 | AB28: found.mthiriet | AC28: MTHIRIETC | AD28: 5484 | AE28: 5484MT | AF28: MTHIRIET@525 | AH28: 45810 | AI28: 45810 | AJ28: 45810 | AK28: 45810 | AL28: #N/A | AM28: #N/A | AN28: #N/A | AO28: #N/A | AP28: #N/A | AQ28: #N/A | AR28: #N/A | AS28: #N/A | AT28: #N/A | AU28: #N/A | AV28: #N/A | AW28: 45807 | AX28: #N/A | AY28: #N/A | AZ28: #N/A | BA28: #N/A | BB28: #N/A | BC28: #N/A | BD28: #N/A | BE28: #N/A | BF28: #N/A | BG28: #N/A | BH28: #N/A | BI28: #N/A | BJ28: #N/A | BK28: 45958 | BM28: 45957 | BN28: 45957 | BO28: #N/A | BP28: #N/A | BQ28: #N/A | BR28: #N/A | BS28: #N/A | BT28: #N/A | BU28: #N/A | BV28: #N/A | BW28: #N/A | BX28: #N/A | BY28: #N/A | BZ28: #N/A | CB28: 45821 | CC28: 1 | CD28: 2025-03 | CF28: #N/A
A29: 28 | B29: 41U648 | C29: 9007723 | D29: 48192112M | E29: INES MARIA SIMON SERRANO | F29: 722769714 | G29: NO | H29: SYR_ABOGADOS_INGLES | I29: AGENT | J29: JURÍDICO | K29: INGLÉS | L29: 45810 | M29: MARIA EMILIA ALEMAN NOCEA | O29: 15_21 | P29: LIBRA | Q29: 15_21 | R29: LFS_15_21 | S29: 15_21 | T29: 10_16 | U29: LIBRA | W29: isimo015 | X29: isimo015@ec.foundever.com | Y29: 3485629 | Z29: 3486659 | AB29: found.imsimon | AC29: ISIMONS | AD29: 5279 | AE29: 5279IS | AF29: IMSIMON@525 | AH29: 45810 | AI29: 45810 | AJ29: 45810 | AK29: 45810 | AL29: #N/A | AM29: #N/A | AN29: #N/A | AO29: #N/A | AP29: #N/A | AQ29: #N/A | AR29: #N/A | AS29: #N/A | AT29: #N/A | AU29: #N/A | AV29: #N/A | AW29: 45807 | AX29: #N/A | AY29: #N/A | AZ29: #N/A | BA29: #N/A | BB29: #N/A | BC29: #N/A | BD29: #N/A | BE29: #N/A | BF29: #N/A | BG29: #N/A | BH29: #N/A | BI29: #N/A | BJ29: #N/A | BK29: 45964 | BM29: 45957 | BN29: 45957 | BO29: #N/A | BP29: #N/A | BQ29: #N/A | BR29: #N/A | BS29: #N/A | BT29: #N/A | BU29: #N/A | BV29: #N/A | BW29: #N/A | BX29: #N/A | BY29: #N/A | BZ29: #N/A | CB29: 45821 | CC29: 1 | CD29: 2025-03 | CF29: #N/A
A30: 29 | B30: 41U165 | C30: 9007138 | D30: 45809739H | E30: HELENA MARIA BAYON MATUTE | F30: 699720032 | G30: NO | H30: SYR_ABOGADOS_INGLES | I30: AGENT | J30: JURÍDICO | K30: INGLÉS | L30: 45684 | M30: MARIA EMILIA ALEMAN NOCEA | O30: 12_20 | P30: 13_20 | Q30: LIBRA | R30: LFS_12_20 | S30: 12_20 | T30: CB_LIBRA | U30: LIBRA | W30: hbayo007 | X30: hbayo007@ec.sitel.com | Y30: 3485977 | Z30: 3486462 | AB30: found.hmbayon | AC30: HMBAYON | AD30: 5889B | AE30: 5889HB | AF30: HMBAYON@525 | AH30: 45684 | AI30: 45684 | AJ30: 45684 | AK30: 45684 | AL30: #N/A | AM30: #N/A | AN30: #N/A | AO30: #N/A | AP30: #N/A | AQ30: #N/A | AR30: #N/A | AS30: #N/A | AT30: #N/A | AU30: #N/A | AV30: #N/A | AW30: 45755 | AX30: #N/A | AY30: #N/A | AZ30: #N/A | BA30: #N/A | BB30: #N/A | BC30: #N/A | BD30: #N/A | BE30: #N/A | BF30: #N/A | BG30: #N/A | BH30: #N/A | BI30: #N/A | BJ30: #N/A | BK30: 45964 | BM30: 45957 | BN30: 45957 | BO30: #N/A | BP30: #N/A | BQ30: #N/A | BR30: #N/A | BS30: #N/A | BT30: #N/A | BU30: #N/A | BV30: #N/A | BW30: #N/A | BX30: #N/A | BY30: #N/A | BZ30: #N/A | CB30: 45734 | CC30: 1 | CD30: 2024-23 | CF30: #N/A
A31: 30 | B31: 41U759 | C31: 9007859 | D31: 29496505V | E31: HALIMA IDRISSI ALCARAZ | F31: 631237990 | G31: NO | H31: SYR_ABOGADOS_INGLES | I31: AGENT | J31: JURÍDICO | K31: INGLES | L31: 45831 | M31: OSCAR EDUARDO CAÑIZALEZ PEREZ | O31: 12_18 | P31: 12_18 | Q31: 12_18 | R31: 12_18 | S31: 12_18 | T31: LIBRA | U31: LIBRA | W31: hidri014 | X31: hidri014@ec.foundever.com | Y31: 3487100 | Z31: 3486766 | AB31: found.hidrissi | AC31: HALIDRI | AD31: 26276 | AE31: 6276HI | AF31: 0 | AH31: 45831 | AI31: 45831 | AJ31: 45831 | AK31: 45831 | AL31: #N/A | AM31: #N/A | AN31: #N/A | AO31: #N/A | AP31: #N/A | AQ31: #N/A | AR31: #N/A | AS31: #N/A | AT31: #N/A | AU31: #N/A | AV31: #N/A | AW31: 45828 | AX31: #N/A | AY31: #N/A | AZ31: #N/A | BA31: #N/A | BB31: #N/A | BC31: #N/A | BD31: #N/A | BE31: #N/A | BF31: #N/A | BG31: #N/A | BH31: #N/A | BI31: #N/A | BJ31: #N/A | BK31: 46010 | BM31: #N/A | BN31: #N/A | BO31: #N/A | BP31: #N/A | BQ31: #N/A | BR31: #N/A | BS31: #N/A | BT31: #N/A | BU31: #N/A | BV31: #N/A | BW31: #N/A | BX31: #N/A | BY31: #N/A | BZ31: #N/A | CB31: 45828 | CC31: 1 | CD31: 2025-09 | CF31: #N/A
A32: 31 | B32: 41U171 | C32: 9007142 | D32: 45995153Y | E32: CARMEN OCAÑA TORO | F32: 675916869 | G32: NO | H32: SYR_ABOGADOS_INGLES | I32: AGENT | J32: JURÍDICO | K32: INGLÉS | L32: 45684 | M32: OSCAR EDUARDO CAÑIZALEZ PEREZ | O32: LIBRA | P32: 15_20 | Q32: DLF_15_20 | R32: LFS_15_20 | S32: 15_20 | T32: 15_20 | U32: LIBRA | W32: cocan007 | X32: cocan007@ec.sitel.com | Y32: 3485179 | Z32: 3486676 | AB32: found.cocana | AC32: COCANA | AD32: 5837O | AE32: 5837CO | AF32: COCANA@525 | AH32: 45684 | AI32: 45684 | AJ32: 45684 | AK32: 45684 | AL32: 45906 | AM32: #N/A | AN32: 06/09/2025@ | AO32: #N/A | AP32: #N/A | AQ32: #N/A | AR32: #N/A | AS32: #N/A | AT32: #N/A | AU32: #N/A | AV32: #N/A | AW32: 45757 | AX32: #N/A | AY32: #N/A | AZ32: #N/A | BA32: #N/A | BB32: #N/A | BC32: #N/A | BD32: #N/A | BE32: #N/A | BF32: #N/A | BG32: #N/A | BH32: #N/A | BI32: #N/A | BJ32: #N/A | BK32: 45967 | BM32: #N/A | BN32: #N/A | BO32: #N/A | BP32: #N/A | BQ32: #N/A | BR32: #N/A | BS32: #N/A | BT32: #N/A | BU32: #N/A | BV32: #N/A | BW32: #N/A | BX32: #N/A | BY32: #N/A | BZ32: #N/A | CB32: 45734 | CC32: 1 | CD32: 2024-23 | CF32: #N/A
A33: 32 | B33: 41U900 | C33: 9005200 | D33: 77845720N | E33: ESTEFANIA FLORES INFANTE | F33: 635854104 | G33: NO | H33: SYR_ABOGADOS_INGLES | I33: AGENT | J33: JURÍDICO | K33: INGLÉS | L33: 45873 | M33: OSCAR EDUARDO CAÑIZALEZ PEREZ | O33: 14_22 | P33: 14_22 | Q33: 14_21 | R33: 14_22 | S33: 14_22 | T33: LIBRA | U33: LIBRA | W33: eflor157 | X33: eflor157@ec.foundever.com | Y33: 3485812 | Z33: 3486836 | AB33: FOUND.EFLORES | AC33: EFLORESI | AD33: 5476f | AE33: 5476ef | AF33: EFLORES@525 | AH33: 45873 | AI33: 45873 | AJ33: 45873 | AK33: 45873 | AL33: #N/A | AM33: #N/A | AN33: #N/A | AO33: #N/A | AP33: #N/A | AQ33: #N/A | AR33: #N/A | AS33: #N/A | AT33: #N/A | AU33: #N/A | AV33: #N/A | AW33: 45873 | AX33: #N/A | AY33: #N/A | AZ33: #N/A | BA33: #N/A | BB33: #N/A | BC33: #N/A | BD33: #N/A | BE33: #N/A | BF33: #N/A | BG33: #N/A | BH33: #N/A | BI33: #N/A | BJ33: #N/A | BK33: 45960 | BM33: #N/A | BN33: #N/A | BO33: #N/A | BP33: #N/A | BQ33: #N/A | BR33: #N/A | BS33: #N/A | BT33: #N/A | BU33: #N/A | BV33: #N/A | BW33: #N/A | BX33: #N/A | BY33: #N/A | BZ33: #N/A | CB33: #N/A | CC33: 1 | CD33: 2025-14 | CF33: #N/A
A34: 33 | B34: 41T401 | C34: 1886395 | D34: 07053147J | E34: IRENE MARQUEZ GUISADO | F34: 676864826 | G34: NO | H34: SYR_ABOGADOS_INGLES | I34: AGENT | J34: JURÍDICO | K34: INGLÉS | L34: 45481 | M34: OSCAR EDUARDO CAÑIZALEZ PEREZ | O34: 08_14 | P34: 08_14 | Q34: 08_14 | R34: LFS_08_14 | S34: 08_14 | T34: LIBRA | U34: LIBRA | W34: imarq026 | X34: imarq026@ec.sitel.com | Y34: 3485894 | Z34: 3486613 | AB34: sitel.imarquez | AC34: IREMAGU | AD34: 5518 | AE34: 5518IM | AF34: IMARQUEZ@525 | AH34: 45497 | AI34: 45497 | AJ34: 45497 | AK34: 45497 | AL34: #N/A | AM34: #N/A | AN34: #N/A | AO34: #N/A | AP34: #N/A | AQ34: #N/A | AR34: #N/A | AS34: #N/A | AT34: #N/A | AU34: #N/A | AV34: #N/A | AW34: 45677 | AX34: #N/A | AY34: #N/A | AZ34: #N/A | BA34: #N/A | BB34: #N/A | BC34: #N/A | BD34: #N/A | BE34: #N/A | BF34: #N/A | BG34: #N/A | BH34: #N/A | BI34: #N/A | BJ34: #N/A | BK34: 45958 | BM34: #N/A | BN34: #N/A | BO34: #N/A | BP34: #N/A | BQ34: #N/A | BR34: #N/A | BS34: #N/A | BT34: #N/A | BU34: #N/A | BV34: #N/A | BW34: #N/A | BX34: #N/A | BY34: #N/A | BZ34: #N/A | CB34: #N/A | CC34: 1 | CD34: 2024-12 | CF34: #N/A
A35: 34 | B35: 41T840 | C35: 9006664 | D35: 05711046P | E35: REBECA DIAZ CASTRO | F35: 679916361 | G35: NO | H35: SYR_ABOGADOS_INGLES | I35: AGENT | J35: JURÍDICO | K35: INGLÉS | L35: 45582 | M35: LAURA HERRERA RODRIGUEZ | O35: 07_14 | P35: 07_14 | Q35: VAC_07_15 | R35: VAC_07_15 | S35: 07_15 | T35: LIBRA | U35: LIBRA | W35: rdiaz148 | X35: rdiaz148@ec.sitel.com | Y35: 3487011 | Z35: 3481522 | AB35: sitel.rdiaz | AC35: RDIAZC | AD35: 5775 | AE35: 5775RD | AF35: RDIAZ@525 | AH35: 45582 | AI35: 45582 | AJ35: 45582 | AK35: 45582 | AL35: #N/A | AM35: #N/A | AN35: #N/A | AO35: #N/A | AP35: #N/A | AQ35: #N/A | AR35: #N/A | AS35: #N/A | AT35: #N/A | AU35: #N/A | AV35: #N/A | AW35: 45750 | AX35: #N/A | AY35: #N/A | AZ35: #N/A | BA35: #N/A | BB35: #N/A | BC35: #N/A | BD35: #N/A | BE35: #N/A | BF35: #N/A | BG35: #N/A | BH35: #N/A | BI35: #N/A | BJ35: #N/A | BK35: 45960 | BM35: 45873 | BN35: 45873 | BO35: 46006 | BP35: 45930 | BQ35: #N/A | BR35: #N/A | BS35: #N/A | BT35: #N/A | BU35: #N/A | BV35: #N/A | BW35: #N/A | BX35: #N/A | BY35: #N/A | BZ35: #N/A | CB35: 45728 | CC35: 1 | CD35: 2024-21 | CF35: #N/A
A36: 35 | B36: 41S113 | C36: 1719492 | D36: 80240268F | E36: OLGA MARIA REDONDO RIVAS | F36: 627555942 | G36: NO | H36: SYR_ABOGADOS_INGLES_WH | I36: AGENT | J36: JURÍDICO | K36: INGLÉS | L36: 45481 | M36: MIGUEL CASTILLO LIMON | O36: 14_21 | P36: 14_21 | Q36: CB_LIBRA | R36: LFS_14_21 | S36: 14_21 | T36: 14_21 | U36: LIBRA | W36: oredo005 | X36: oredo005@ec.sitel.com | Y36: 3485938 | Z36: 3486649 | AB36: SITEL.OMREDONDO | AC36: OLMARERI | AD36: 5676 | AE36: 5676OR | AF36: 0 | AH36: 45195 | AI36: 45497 | AJ36: 45497 | AK36: 45497 | AL36: 45681 | AM36: #N/A | AN36: 21/03/2025@ | AO36: #N/A | AP36: #N/A | AQ36: #N/A | AR36: #N/A | AS36: #N/A | AT36: #N/A | AU36: #N/A | AV36: #N/A | AW36: 45582 | AX36: #N/A | AY36: #N/A | AZ36: #N/A | BA36: #N/A | BB36: #N/A | BC36: #N/A | BD36: #N/A | BE36: #N/A | BF36: #N/A | BG36: #N/A | BH36: #N/A | BI36: #N/A | BJ36: #N/A | BK36: #N/A | BM36: 45812 | BN36: 45812 | BO36: 46006 | BP36: #N/A | BQ36: #N/A | BR36: #N/A | BS36: 45812 | BT36: #N/A | BU36: #N/A | BV36: #N/A | BW36: #N/A | BX36: #N/A | BY36: #N/A | BZ36: #N/A | CB36: #N/A | CC36: 1 | CD36: 2024-12 | CF36: #N/A
A37: 36 | B37: 41T461 | C37: 1890116 | D37: 78104116A | E37: FERNANDO GARCIA SOTO | F37: 626202042 | G37: NO | H37: SYR_ABOGADOS_INGLES_WH | I37: AGENT | J37: JURÍDICO | K37: INGLÉS | L37: 45502 | M37: MIGUEL CASTILLO LIMON | O37: 15_22 | P37: @SSYRABING_15_22 | Q37: LIBRA | R37: @SSYRABING_LFS_15_22 | S37: @SSYRABING_15_22 | T37: @SSYRABING_15_22 | U37: LIBRA | W37: fgarc188 | X37: fgarc188@ec.sitel.com | Y37: 3487017 | Z37: 3481520 | AB37: SITEL.FGARCIAS | AC37: FERGARCSOT | AD37: 5971 | AE37: 5971FG | AF37: 0 | AH37: 45514 | AI37: 45514 | AJ37: 45514 | AK37: 45514 | AL37: #N/A | AM37: #N/A | AN37: #N/A | AO37: #N/A | AP37: #N/A | AQ37: #N/A | AR37: #N/A | AS37: #N/A | AT37: #N/A | AU37: 45923 | AV37: 45611 | AW37: 45582 | AX37: #N/A | AY37: #N/A | AZ37: #N/A | BA37: #N/A | BB37: #N/A | BC37: #N/A | BD37: #N/A | BE37: #N/A | BF37: #N/A | BG37: #N/A | BH37: #N/A | BI37: 45569 | BJ37: #N/A | BK37: #N/A | BM37: 45812 | BN37: 45812 | BO37: 45937 | BP37: #N/A | BQ37: #N/A | BR37: 45986 | BS37: 45812 | BT37: #N/A | BU37: #N/A | BV37: #N/A | BW37: #N/A | BX37: #N/A | BY37: #N/A | BZ37: #N/A | CB37: #N/A | CC37: 1 | CD37: 2024-14 | CF37: #N/A
A38: 37 | B38: 41T591 | C38: 9006306 | D38: 49341974M | E38: IRENE DOBLADO ANDRADES | F38: 679153184 | G38: NO | H38: SYR_ABOGADOS_INGLES_WH | I38: AGENT | J38: JURÍDICO | K38: INGLÉS | L38: 45532 | M38: MIGUEL CASTILLO LIMON | O38: LIBRA | P38: @SSYRABING_13_20 | Q38: 13_20 | R38: LFS_13_20 | S38: @SSYRABING_13_20 | T38: @SSYRABING_13_20 | U38: LIBRA | W38: idobl003 | X38: idobl003@ec.sitel.com | Y38: 3485718 | Z38: 3486246 | AB38: SITEL.idoblado | AC38: IDOBLADO | AD38: 26080 | AE38: 6080ID | AF38: 0 | AH38: 45547 | AI38: 45547 | AJ38: 45547 | AK38: 45547 | AL38: #N/A | AM38: #N/A | AN38: #N/A | AO38: #N/A | AP38: #N/A | AQ38: #N/A | AR38: #N/A | AS38: #N/A | AT38: #N/A | AU38: 45923 | AV38: 45623 | AW38: 45586 | AX38: #N/A | AY38: #N/A | AZ38: #N/A | BA38: #N/A | BB38: #N/A | BC38: #N/A | BD38: #N/A | BE38: #N/A | BF38: #N/A | BG38: #N/A | BH38: #N/A | BI38: #N/A | BJ38: #N/A | BK38: #N/A | BM38: 45812 | BN38: 45812 | BO38: #N/A | BP38: #N/A | BQ38: #N/A | BR38: #N/A | BS38: 45812 | BT38: #N/A | BU38: #N/A | BV38: #N/A | BW38: #N/A | BX38: 45944 | BY38: #N/A | BZ38: #N/A | CB38: #N/A | CC38: 1 | CD38: 2024-17 | CF38: #N/A
A39: 38 | B39: 41T258 | C39: 1879155 | D39: Z1610970D | E39: ADA ALICIA WELCHEZ ROBLES | F39: 613747157 | G39: NO | H39: SYR_ABOGADOS_INGLES_WH | I39: AGENT | J39: JURÍDICO | K39: INGLÉS | L39: 45446 | M39: NIKOLAY NAZAROV | O39: 08_15 | P39: 08_15 | Q39: 08_15 | R39: 08_15 | S39: 08_15 | T39: LIBRA | U39: LIBRA | W39: awelc038 | X39: awelc038@ec.sitel.com | Y39: 3485953 | Z39: 3486653 | AB39: SITEL.AAWELCHEZ | AC39: AWELCHEZ | AD39: 5928 | AE39: 5928AW | AF39: AAWELCHEZ@525 | AH39: 45460 | AI39: 45460 | AJ39: 45460 | AK39: 45460 | AL39: 45681 | AM39: #N/A | AN39: #N/A | AO39: #N/A | AP39: #N/A | AQ39: #N/A | AR39: #N/A | AS39: #N/A | AT39: #N/A | AU39: #N/A | AV39: #N/A | AW39: 45614 | AX39: #N/A | AY39: #N/A | AZ39: #N/A | BA39: #N/A | BB39: #N/A | BC39: #N/A | BD39: #N/A | BE39: #N/A | BF39: #N/A | BG39: #N/A | BH39: #N/A | BI39: #N/A | BJ39: #N/A | BK39: 45968 | BM39: 45812 | BN39: 45812 | BO39: #N/A | BP39: 45930 | BQ39: #N/A | BR39: #N/A | BS39: 45812 | BT39: #N/A | BU39: #N/A | BV39: #N/A | BW39: #N/A | BX39: #N/A | BY39: #N/A | BZ39: #N/A | CB39: 45726 | CC39: 1 | CD39: 2024-08 | CF39: #N/A
A40: 39 | B40: 41T328 | C40: 1883633 | D40: 20604386C | E40: MARINA CHACON ESPAÑA | F40: 687237556 | G40: NO | H40: SYR_ABOGADOS_INGLES_WH | I40: AGENT | J40: JURÍDICO | K40: INGLÉS | L40: 45464 | M40: PATRICIA MARTINEZ ALONSO | O40: 15_22 | P40: 15_22 | Q40: 15_22 | R40: LFS_15_22 | S40: 15_22 | T40: LIBRA | U40: LIBRA | W40: mchac039 | X40: mchac039@ec.sitel.com | Y40: 3485969 | Z40: 3486669 | AB40: SITEL.MCHACON | AC40: MARINCH | AD40: 5690 | AE40: 5690MC | AF40: 0 | AH40: 45481 | AI40: 45481 | AJ40: 45481 | AK40: 45481 | AL40: #N/A | AM40: #N/A | AN40: #N/A | AO40: #N/A | AP40: #N/A | AQ40: #N/A | AR40: #N/A | AS40: #N/A | AT40: #N/A | AU40: #N/A | AV40: #N/A | AW40: 45677 | AX40: #N/A | AY40: #N/A | AZ40: #N/A | BA40: #N/A | BB40: #N/A | BC40: #N/A | BD40: #N/A | BE40: #N/A | BF40: #N/A | BG40: #N/A | BH40: #N/A | BI40: #N/A | BJ40: #N/A | BK40: #N/A | BM40: 45862 | BN40: 45862 | BO40: #N/A | BP40: #N/A | BQ40: #N/A | BR40: #N/A | BS40: 45862 | BT40: #N/A | BU40: #N/A | BV40: #N/A | BW40: #N/A | BX40: #N/A | BY40: #N/A | BZ40: #N/A | CB40: #N/A | CC40: 1 | CD40: 2024-10 | CF40: #N/A
...

Sheet CAMBIAR USB
A1: ID_EMPL | B1: ID_BOOST | C1: DNI | D1: NOMBRE | E1: TM | F1: TLF | G1: ENTREGADO
A2: 41K443 | B2: 9002826 | C2: 30235487D | D2: ABEL ANDRES PARRA FUENTES | E2: JOGREG HENRIQUEZ AELLOS | F2: 722236393 | I2: SI
A3: 41W001 | B3: 9000017 | C3: Y5055589L | D3: ABNER JOSE TEHN MUTTACH | E3: JESUS DENIZ PRADOS | F3: 644605589 | I3: NO
A4: 416305 | B4: 9001101 | C4: 53351822X | D4: ADRIAN LOPEZ MAYA | E4: SORAYA RAMOS PAREDES | F4: 660263206 | I4: TRABAJA DESDE EL SITE
A5: 41J724 | B5: 9002618 | C5: 28832465X | D5: ADRIANA ROBLES ARCOS | E5: ANA MARIA DIAZ PURA | F5: 626282555 | G5: SI
A6: 414909 | B6: 9000486 | C6: 52288528Y | D6: AGUASANTA ORTEGA GOMEZ | E6: CRISTIAN JOSE MORENO BERLANGA | F6: ELIMINADO RGDP
A7: 41I925 | B7: 9002542 | C7: X1941215S | D7: ALDO GUARINI | E7: ROCIO LEAL HURTADO | F7: 601151761 | G7: SI
A8: 417221 | B8: 9000982 | C8: 53277480G | D8: ALEJANDRA CABEZAS PEDRAZA | E8: ANTONIO MANUEL VARGAS HERRERA | F8: 653447825
A9: 41G606 | B9: 9003164 | C9: 73010243D | D9: ALEJANDRA CENTRON BROCO | E9: JOSE ANTONIO CAMACHO ROMANO | F9: 630145191
A10: 41F115 | B10: 9003540 | C10: 25593929N | D10: ALEJANDRO MORENO SANCHEZ | E10: MARIA EMILIA ALEMAN NOCEA | F10: 639511094 | G10: SI
A11: 41H199 | B11: 9003557 | C11: 28827260A | D11: ALEJANDRO SANZ ZAMBRANO | E11: LUIS MIGUEL ENCARNACAO CORTES | F11: 657993036
A12: 41G006 | B12: 9003138 | C12: Y0113442C | D12: ALETHEIA ROSA LUCIO | E12: ROCIO LEAL HURTADO | F12: 605523370
A13: 41J711 | B13: 9002610 | C13: 53280484H | D13: ALICIA LEON PIRSON | E13: JOSE ANTONIO CAMACHO ROMANO | F13: 617734694
A14: 41F998 | B14: 9003135 | C14: 48460863R | D14: ALICIA LOPEZ LOPEZ | E14: JESUS DENIZ PRADOS | F14: 649887884
A15: 41H363 | B15: 9003113 | C15: 48875523V | D15: ALONSO MONTOYA NAVARRO | E15: FREDWAR ALBERTO SEQUERA OLIVEROS | F15: 663459936
A16: 41M625 | B16: 9005234 | C16: 30241761G | D16: ALVARO PEINADO RUIZ | E16: FREDWAR ALBERTO SEQUERA OLIVEROS | F16: 677891661
A17: 41H839 | B17: 9003105 | C17: 48618953N | D17: ANA BEJARANO CORDERO | E17: JOGREG HENRIQUEZ AELLOS | F17: 665932821
A18: 41D719 | B18: 9001428 | C18: 27317518G | D18: ANA BELEN FERNANDEZ CASERO | E18: MARIA EMILIA ALEMAN NOCEA | F18: 687225393
A19: 41H193 | B19: 9003551 | C19: 28817053P | D19: ANA INFANTE ZUMER | E19: JOSE ANTONIO CAMACHO ROMANO | F19: 618379711
A20: 41H197 | B20: 9003555 | C20: 28615647J | D20: ANA ISABEL MUÑOZ GARCIA | E20: CRISTIAN JOSE MORENO BERLANGA | F20: 645716634
A21: 41K434 | B21: 9002821 | C21: 28836522L | D21: ANA KLEISCH CASCAJO | E21: JESUS NICOLAS BECERRA BARBA | F21: 633485115
A22: 41J753 | B22: 9002251 | C22: 77814122Q | D22: ANA MARIA CORRO CARRERA | E22: JESUS NICOLAS BECERRA BARBA | F22: 659738951
A23: 410641 | B23: 9000075 | C23: 28585919R | D23: ANA MARIA GAVIRA MUÑOZ | E23: FREDWAR ALBERTO SEQUERA OLIVEROS | F23: 954406621
A24: 418649 | B24: 9001011 | C24: 28844386V | D24: ANA MARIA RODRIGUEZ GAVIRA | E24: ROCIO LEAL HURTADO | F24: 692386517
A25: 41E998 | B25: 9003027 | C25: 28594373Z | D25: ANA MATEO SANCHEZ | E25: CRISTIAN JOSE MORENO BERLANGA | F25: 609648168
A26: 41P283 | B26: 1543539 | C26: 30267248F | D26: ANA RODRIGUEZ RIASCO | E26: TANIA CACERES DROGUET | F26: 644810616
A27: 41F991 | B27: 9003132 | C27: X7277758Y | D27: ANDREA MARIA ACQUALAGNA | E27: ROCIO LEAL HURTADO | F27: 606692040
A28: 41B458 | B28: 9001696 | C28: 53275666F | D28: ANGEL RODRIGUEZ FORERO | E28: ANA MARIA DIAZ PURA | F28: PDTE
A29: 41K392 | B29: 9002096 | C29: X3276882A | D29: ANGELA DANIELA CABRAL LOUSADA | E29: LUIS MIGUEL ENCARNACAO CORTES | F29: 662506848
A30: 41I120 | B30: 9002337 | C30: 44954311Y | D30: ANGELES MARIA CARMONA MARQUEZ | E30: IVAN BAEZA AGUILERA | F30: 633697522
A31: 412591 | B31: 9000572 | C31: 28883994L | D31: ANTONIA MUÑOZ LUNA | E31: LUNA MORILLO FUENTES | F31: 660348118
A32: 41G632 | B32: 9003390 | C32: 28865924G | D32: ANTONIO JESUS DEL CUETO MUÑOZ | E32: ROCIO LEAL HURTADO | F32: 654543703
A33: 41F993 | B33: 9003134 | C33: 75817974S | D33: BEATRIZ ARCE CAILLAUD | E33: CRISTIAN JOSE MORENO BERLANGA | F33: 670060173
A34: 41F098 | B34: 9003010 | C34: 45806583J | D34: BEATRIZ CARMONA FUENTES | E34: CRISTIAN JOSE MORENO BERLANGA | F34: 687377028
A35: 41M617 | B35: 9005251 | C35: 47564441G | D35: BELEN DE LUQUE JIMENEZ | E35: TANIA CACERES DROGUET | F35: 627098947
A36: 41K126 | B36: 9002019 | C36: 49031766K | D36: BLANCA REY LOPEZ | E36: ANA MARIA DIAZ PURA | F36: 659984642
A37: 41K247 | B37: 9001983 | C37: Y2259824L | D37: CAIO CESAR DA SILVA | E37: ANTONIO MANUEL VARGAS HERRERA | F37: 681053963
A38: 41I940 | B38: 9002547 | C38: Y5522456D | D38: CALEBE SIMOES DE SOUZA | E38: LUIS MIGUEL ENCARNACAO CORTES | F38: 686572115
A39: 41H194 | B39: 9003552 | C39: Y1736508E | D39: CAMILA MALLET COSTA | E39: MARIA EMILIA ALEMAN NOCEA | F39: 664131692
A40: 41J757 | B40: 9002255 | C40: 53294281S | D40: CARLA FERNANDEZ GOMEZ | E40: JESUS DENIZ PRADOS | F40: 615049183
...
